Workbook

Sheet data
C6: Experiment 1 - Tracker 1 - UWB 1 | F6: MQTT | N6: Matter | W6: Experiment 1 - Tracker 2- UWB 2 | Z6: MQTT | AH6: Matter | AQ6: Experiment 1 - Tracker 3 - UWB 3 | AT6: MQTT | BB6: Matter | BK6: Experiment 1 - Tracker 4 - UWB 4 | BN6: MQTT | BV6: Matter | CE6: Experiment 1 - Tracker 5 - BLE 1 | CH6: MQTT | CP6: Matter | CY6: Experiment 1 - Tracker 6 - BLE 2 | DB6: MQTT | DJ6: Matter | DS6: Experiment 1 - Tracker 7 - BLE 3 | DV6: MQTT | ED6: Matter | EM6: Experiment 1 - Tracker 8 - BLE 4 | EP6: MQTT | EX6: Matter
C7: Vol. | D7: Ground Truth Source | F7: A1 | G7: A2 | H7: A3 | I7: A4 | J7: A5 | K7: A6 | L7: A7 | M7: A8 | N7: A1 | O7: A2 | P7: A3 | Q7: A4 | R7: A5 | S7: A6 | T7: A7 | U7: A8 | W7: Vol. | X7: Ground Truth Source | Z7: A1 | AA7: A2 | AB7: A3 | AC7: A4 | AD7: A5 | AE7: A6 | AF7: A7 | AG7: A8 | AH7: A1 | AI7: A2 | AJ7: A3 | AK7: A4 | AL7: A5 | AM7: A6 | AN7: A7 | AO7: A8 | AQ7: Vol. | AR7: Ground Truth Source | AT7: A1 | AU7: A2 | AV7: A3 | AW7: A4 | AX7: A5 | AY7: A6 | AZ7: A7 | BA7: A8 | BB7: A1 | BC7: A2 | BD7: A3 | BE7: A4 | BF7: A5 | BG7: A6 | BH7: A7 | BI7: A8 | BK7: Vol. | BL7: Ground Truth Source | BN7: A1 | BO7: A2 | BP7: A3 | BQ7: A4 | BR7: A5 | BS7: A6 | BT7: A7 | BU7: A8 | BV7: A1 | BW7: A2 | BX7: A3 | BY7: A4 | BZ7: A5 | CA7: A6 | CB7: A7 | CC7: A8 | CE7: Vol. | CF7: Ground Truth Source | CH7: A1 | CI7: A2 | CJ7: A3 | CK7: A4 | CL7: A5 | CM7: A6 | CN7: A7 | CO7: A8 | CP7: A1 | CQ7: A2 | CR7: A3 | CS7: A4 | CT7: A5 | CU7: A6 | CV7: A7 | CW7: A8 | CY7: Vol. | CZ7: Ground Truth Source | DB7: A1 | DC7: A2 | DD7: A3 | DE7: A4 | DF7: A5 | DG7: A6 | DH7: A7 | DI7: A8 | DJ7: A1 | DK7: A2 | DL7: A3 | DM7: A4 | DN7: A5 | DO7: A6 | DP7: A7 | DQ7: A8 | DS7: Vol. | DT7: Ground Truth Source | DV7: A1 | DW7: A2 | DX7: A3 | DY7: A4 | DZ7: A5 | EA7: A6 | EB7: A7 | EC7: A8 | ED7: A1 | EE7: A2 | EF7: A3 | EG7: A4 | EH7: A5 | EI7: A6 | EJ7: A7 | EK7: A8 | EM7: Vol. | EN7: Ground Truth Source | EP7: A1 | EQ7: A2 | ER7: A3 | ES7: A4 | ET7: A5 | EU7: A6 | EV7: A7 | EW7: A8 | EX7: A1 | EY7: A2 | EZ7: A3 | FA7: A4 | FB7: A5 | FC7: A6 | FD7: A7 | FE7: A8
C8: 1 | D8: Mean unfiltered value | F8: 2.8996154 | G8: 4.2384 | H8: 5.0367308 | I8: 5.1010628 | J8: 4.0803865 | K8: 4.5046635 | L8: 1.7265686 | M8: 2.3231068 | N8: 2.8822 | O8: 4.289375 | P8: 5.1958 | Q8: 4.9467347 | R8: 4.0396 | S8: 4.5356 | T8: 1.7266 | U8: 2.2914 | W8: 1 | X8: Mean unfiltered value | Z8: 2.7501408 | AA8: 5.0811268 | AB8: 5.0657746 | AC8: 5.3908451 | AD8: 5.0266667 | AE8: 3.4778873 | AF8: 2.796 | AG8: 3.2876471 | AH8: 2.7088889 | AI8: 5.2342222 | AJ8: 5.0442222 | AK8: 5.3868889 | AL8: 5.218 | AM8: 3.4102222 | AN8: 2.7924444 | AO8: 3.2990909 | AQ8: 1 | AR8: Mean unfiltered value | AT8: 3.7551575 | AU8: 4.0550787 | AV8: 4.0126482 | AW8: 4.2034387 | AX8: 3.444664 | AY8: 2.9988189 | AZ8: 1.5999213 | BA8: 1.22932 | BB8: 3.7646 | BC8: 4.1638 | BD8: 4.1056 | BE8: 4.1536 | BF8: 3.3826 | BG8: 3.0268 | BH8: 1.6202 | BI8: 1.2238776 | BK8: 1 | BL8: Mean unfiltered value | BN8: 3.8551261 | BO8: 5.8413445 | BP8: 3.6062185 | BQ8: 4.9131356 | BR8: 5.2335897 | BS8: 1.8060504 | BT8: 3.4309244 | BU8: 3.1077011 | BV8: 3.838 | BW8: 5.9632727 | BX8: 3.612 | BY8: 5.0389091 | BZ8: 5.325283 | CA8: 1.814 | CB8: 3.3509091 | CC8: 3.187381 | CE8: 1 | CF8: Mean unfiltered value | CH8: 2.8744 | CI8: 1.2947917 | CJ8: 2.7509615 | CK8: 3.7483051 | CL8: 1.7544068 | CM8: 6.434375 | CN8: 1.0323729 | CO8: 2.2596 | CY8: 1 | CZ8: Mean unfiltered value | DB8: 0.59644068 | DC8: 3.0077966 | DD8: 0.41610169 | DE8: 1.8201695 | DF8: 5.6222034 | DG8: 2.1145763 | DH8: 0.67372881 | DI8: 1.5407143 | DJ8: 0.58666667 | DK8: 2.5053333 | DL8: 0.27533333 | DM8: 1.7426667 | DN8: 6.1833333 | DO8: 1.7593333 | DP8: 0.64866667 | DQ8: 1.4373333 | DS8: 1 | DT8: Mean unfiltered value | DV8: 12.188305 | DW8: 1.275 | DX8: 1.4925424 | DY8: 3.1598182 | DZ8: 1.7196552 | EA8: 2.4876271 | EB8: 0.24810345 | EC8: 0.27355932 | ED8: 12.318 | EE8: 1.15 | EF8: 1.247 | EG8: 3.226 | EH8: 1.71 | EI8: 2.677 | EJ8: 0.22222222 | EK8: 0.298 | EM8: 1 | EN8: Mean unfiltered value | EP8: 0.81851064 | EQ8: 1.3184746 | ER8: 0.14694915 | ES8: 2.027234 | ET8: 1.8788889 | EU8: 0.61881356 | EV8: 0.30745763 | EW8: 2.490678 | EX8: 0.81416667 | EY8: 1.3941667 | EZ8: 0.151 | FA8: 2.027234 | FB8: 1.8790909 | FC8: 0.6225 | FD8: 0.30866667 | FE8: 2.459
D9: Standard deviation | F9: 0.45088624 | G9: 0.66287742 | H9: 0.79596803 | I9: 1.2207613 | J9: 0.77704996 | K9: 0.93894374 | L9: 0.19275802 | M9: 0.3955978 | N9: 0.47963119 | O9: 0.54140639 | P9: 0.46422677 | Q9: 1.3693328 | R9: 0.81081707 | S9: 0.90124666 | T9: 0.221577 | U9: 0.29508221 | X9: Standard deviation | Z9: 0.42273089 | AA9: 1.2370363 | AB9: 0.49876608 | AC9: 1.237735 | AD9: 0.74212533 | AE9: 0.75597792 | AF9: 0.68180579 | AG9: 0.60097959 | AH9: 0.5304808 | AI9: 1.0337644 | AJ9: 0.57403635 | AK9: 1.331228 | AL9: 0.10495713 | AM9: 0.86341052 | AN9: 0.6875307 | AO9: 0.5939116 | AR9: Standard deviation | AT9: 0.61039786 | AU9: 0.72245177 | AV9: 0.60750245 | AW9: 0.54906742 | AX9: 0.60604395 | AY9: 0.49743073 | AZ9: 0.17557133 | BA9: 0.1258 | BB9: 0.57428289 | BC9: 0.59551621 | BD9: 0.34879312 | BE9: 0.74820254 | BF9: 0.70212196 | BG9: 0.44433519 | BH9: 0.083821 | BI9: 0.12972209 | BL9: Standard deviation | BN9: 0.87165328 | BO9: 0.866357 | BP9: 0.54601327 | BQ9: 0.89901247 | BR9: 0.69208762 | BS9: 0.20627536 | BT9: 0.87855717 | BU9: 0.52223514 | BV9: 1.0032971 | BW9: 0.54635671 | BX9: 0.51864298 | BY9: 0.80741489 | BZ9: 0.47046185 | CA9: 0.17447688 | CB9: 1.0125526 | CC9: 0.13746098 | CF9: Standard deviation | CH9: 2.7835172 | CI9: 0.62430213 | CJ9: 1.3581811 | CK9: 2.3801363 | CL9: 1.3535066 | CM9: 18.821901 | CN9: 0.40578293 | CO9: 0.95837745 | CZ9: Standard deviation | DB9: 0.20662946 | DC9: 1.5069609 | DD9: 0.71150646 | DE9: 0.63358991 | DF9: 6.4190554 | DG9: 1.3530187 | DH9: 0.079738761 | DI9: 1.0148316 | DJ9: 0.21164961 | DK9: 1.6478465 | DL9: 0.11557778 | DM9: 0.49494062 | DN9: 6.8096066 | DO9: 0.13968854 | DP9: 0.093156976 | DQ9: 0.73883211 | DT9: Standard deviation | DV9: 2.2317352 | DW9: 0.20813457 | DX9: 1.3823887 | DY9: 0.72508873 | DZ9: 0.24481261 | EA9: 0.6288011 | EB9: 0.17772892 | EC9: 0.15401257 | ED9: 0.744 | EE9: 0.2714406 | EF9: 0.68499708 | EG9: 0.668 | EH9: 0.24931907 | EI9: 0.50854793 | EJ9: 0.01987616 | EK9: 0.1980303 | EN9: Standard deviation | EP9: 0.076867439 | EQ9: 2.1886682 | ER9: 0.028481951 | ES9: 1.9938936 | ET9: 0.46142792 | EU9: 0.16958453 | EV9: 0.050020452 | EW9: 0.63831368 | EX9: 0.077131742 | EY9: 2.2631544 | EZ9: 0.036226142 | FA9: 1.9725679 | FB9: 0.45296306 | FC9: 0.16792483 | FD9: 0.049209304 | FE9: 0.64524078
D10: Mean filtered value | F10: 3 | G10: 4.39 | H10: 5.3 | I10: 5.46 | J10: 4.32 | K10: 4.79 | L10: 1.75 | M10: 2.27 | N10: 3.0019565 | O10: 4.3963043 | P10: 5.2955319 | Q10: 5.3625 | R10: 4.3236364 | S10: 4.8073333 | T10: 1.7577551 | U10: 2.2547727 | X10: Mean filtered value | Z10: 2.8377612 | AA10: 5.4406154 | AB10: 5.1660294 | AC10: 5.8579661 | AD10: 5.2675 | AE10: 3.7246032 | AF10: 3.0245161 | AG10: 3.4040351 | AH10: 2.837381 | AI10: 5.4569767 | AJ10: 5.1665116 | AK10: 5.8723684 | AL10: 5.145 | AM10: 3.6690244 | AN10: 3.01375 | AO10: 3.4257143 | AR10: Mean filtered value | AT10: 3.9142128 | AU10: 4.2569957 | AV10: 4.1589831 | AW10: 4.3022131 | AX10: 3.598178 | AY10: 3.1259402 | AZ10: 1.6292276 | BA10: 1.2435124 | BB10: 3.9180435 | BC10: 4.2722917 | BD10: 4.1553061 | BE10: 4.3054167 | BF10: 3.604 | BG10: 3.1255319 | BH10: 1.6318367 | BI10: 1.2387234 | BL10: Mean filtered value | BN10: 4.1203738 | BO10: 6.0938532 | BP10: 3.7511927 | BQ10: 5.1123762 | BR10: 5.3855455 | BS10: 1.8475439 | BT10: 3.7243396 | BU10: 3.1539744 | BV10: 4.1538 | BW10: 6.0915385 | BX10: 3.759 | BY10: 5.1698 | BZ10: 5.4377551 | CA10: 1.8477358 | CB10: 3.7258333 | CC10: 3.1673171 | CF10: Mean filtered value | CH10: 2.32125 | CI10: 1.1415556 | CJ10: 2.5597917 | CK10: 3.3131579 | CL10: 1.3932727 | CM10: 1.6913333 | CN10: 1.2609091 | CO10: 2.8852941 | CZ10: Mean filtered value | DB10: 0.53592593 | DC10: 3.8362791 | DD10: 0.32431034 | DE10: 1.6115094 | DF10: 2.266087 | DG10: 1.8057143 | DH10: 0.69 | DI10: 1.1956 | DJ10: 0.53071429 | DK10: 3.56 | DL10: 0.35888889 | DM10: 1.6128571 | DN10: 2.0936364 | DO10: 1.89 | DP10: 0.67923077 | DQ10: 1.2414286 | DT10: Mean filtered value | DV10: 12.260769 | DW10: 1.3477778 | DX10: 1.3315517 | DY10: 3.4609524 | DZ10: 1.7966667 | EA10: 2.4093878 | EB10: 0.21517857 | EC10: 0.21122449 | ED10: 12.69 | EE10: 1.37 | EF10: 1.69 | EG10: 3.56 | EH10: 1.82 | EI10: 2.45625 | EJ10: 0.24 | EK10: 0.23666667 | EN10: Mean filtered value | EP10: 0.85 | EQ10: 0.59754717 | ER10: 0.14735849 | ES10: 1.5354545 | ET10: 2.0578261 | EU10: 0.70023256 | EV10: 0.29704545 | EW10: 2.2176596 | EX10: 0.85 | EY10: 0.58132075 | EZ10: 0.14777778 | FA10: 1.5354545 | FB10: 2.0542553 | FC10: 0.70340909 | FD10: 0.29888889 | FE10: 2.1959574
D11: Laser | E11: Ground Truth | F11: 3.04 | G11: 4.01 | H11: 5.24 | I11: 5.77 | J11: 4.19 | K11: 4.38 | L11: 1.55 | M11: 2.41 | N11: 3.04 | O11: 4.01 | P11: 5.24 | Q11: 5.77 | R11: 4.19 | S11: 4.38 | T11: 1.55 | U11: 2.41 | X11: Laser | Y11: Ground Truth | Z11: 2.88 | AA11: 5.31 | AB11: 5.04 | AC11: 6.21 | AD11: 5.29 | AE11: 3.65 | AF11: 2.85 | AG11: 3.06 | AH11: 2.88 | AI11: 5.31 | AJ11: 5.04 | AK11: 6.21 | AL11: 5.29 | AM11: 3.65 | AN11: 2.85 | AO11: 3.06 | AR11: Laser | AS11: Ground Truth | AT11: 3.88 | AU11: 4.23 | AV11: 3.88 | AW11: 4.43 | AX11: 3.58 | AY11: 3.17 | AZ11: 1.72 | BA11: 1.14 | BB11: 3.88 | BC11: 4.23 | BD11: 3.88 | BE11: 4.43 | BF11: 3.58 | BG11: 3.17 | BH11: 1.72 | BI11: 1.14 | BL11: Laser | BM11: Ground Truth | BN11: 4.2 | BO11: 6.08 | BP11: 3.62 | BQ11: 5.36 | BR11: 5.44 | BS11: 1.82 | BT11: 3.76 | BU11: 2.87 | BV11: 4.2 | BW11: 6.08 | BX11: 3.62 | BY11: 5.36 | BZ11: 5.44 | CA11: 1.82 | CB11: 3.76 | CC11: 2.87 | CF11: Laser | CG11: Ground Truth | CH11: 3.04 | CI11: 4.01 | CJ11: 5.24 | CK11: 5.77 | CL11: 4.19 | CM11: 4.38 | CN11: 1.55 | CO11: 2.41 | CZ11: Laser | DA11: Ground Truth | DB11: 2.88 | DC11: 5.31 | DD11: 5.04 | DE11: 6.21 | DF11: 5.29 | DG11: 3.65 | DH11: 2.85 | DI11: 3.06 | DJ11: 2.88 | DK11: 5.31 | DL11: 5.04 | DM11: 6.21 | DN11: 5.29 | DO11: 3.65 | DP11: 2.85 | DQ11: 3.06 | DT11: Laser | DU11: Ground Truth | DV11: 3.88 | DW11: 4.23 | DX11: 3.88 | DY11: 4.43 | DZ11: 3.58 | EA11: 3.17 | EB11: 1.72 | EC11: 1.14 | ED11: 3.88 | EE11: 4.23 | EF11: 3.88 | EG11: 4.43 | EH11: 3.58 | EI11: 3.17 | EJ11: 1.72 | EK11: 1.14 | EN11: Laser | EO11: Ground Truth | EP11: 4.2 | EQ11: 6.08 | ER11: 3.62 | ES11: 5.36 | ET11: 5.44 | EU11: 1.82 | EV11: 3.76 | EW11: 2.87 | EX11: 4.2 | EY11: 6.08 | EZ11: 3.62 | FA11: 5.36 | FB11: 5.44 | FC11: 1.82 | FD11: 3.76 | FE11: 2.87
E12: Error [m] | F12: 0.04 | G12: -0.38 | H12: -0.06 | I12: 0.31 | J12: -0.13 | K12: -0.41 | L12: -0.2 | M12: 0.14 | N12: 0.038043478 | O12: -0.38630435 | P12: -0.055531915 | Q12: 0.4075 | R12: -0.13363636 | S12: -0.42733333 | T12: -0.2077551 | U12: 0.15522727 | Y12: Error [m] | Z12: 0.042238806 | AA12: -0.13061538 | AB12: -0.12602941 | AC12: 0.3520339 | AD12: 0.0225 | AE12: -0.074603175 | AF12: -0.17451613 | AG12: -0.34403509 | AH12: 0.042619048 | AI12: -0.14697674 | AJ12: -0.12651163 | AK12: 0.33763158 | AL12: 0.145 | AM12: -0.01902439 | AN12: -0.16375 | AO12: -0.36571429 | AS12: Error [m] | AT12: -0.034212766 | AU12: -0.026995708 | AV12: -0.27898305 | AW12: 0.12778689 | AX12: -0.018177966 | AY12: 0.044059829 | AZ12: 0.090772358 | BA12: -0.1035124 | BB12: -0.038043478 | BC12: -0.042291667 | BD12: -0.27530612 | BE12: 0.12458333 | BF12: -0.024 | BG12: 0.044468085 | BH12: 0.088163265 | BI12: -0.098723404 | BM12: Error [m] | BN12: 0.079626168 | BO12: -0.013853211 | BP12: -0.13119266 | BQ12: 0.24762376 | BR12: 0.054454545 | BS12: -0.02754386 | BT12: 0.035660377 | BU12: -0.28397436 | BV12: 0.0462 | BW12: -0.011538462 | BX12: -0.139 | BY12: 0.1902 | BZ12: 0.002244898 | CA12: -0.027735849 | CB12: 0.034166667 | CC12: -0.29731707 | CG12: Error [m] | CH12: 0.71875 | CI12: 2.8684444 | CJ12: 2.6802083 | CK12: 2.4568421 | CL12: 2.7967273 | CM12: 2.6886667 | CN12: 0.28909091 | CO12: -0.47529412 | DA12: Error [m] | DB12: 2.3440741 | DC12: 1.4737209 | DD12: 4.7156897 | DE12: 4.5984906 | DF12: 3.023913 | DG12: 1.8442857 | DH12: 2.16 | DI12: 1.8644 | DJ12: 2.3492857 | DK12: 1.75 | DL12: 4.6811111 | DM12: 4.5971429 | DN12: 3.1963636 | DO12: 1.76 | DP12: 2.1707692 | DQ12: 1.8185714 | DU12: Error [m] | DV12: -8.3807692 | DW12: 2.8822222 | DX12: 2.5484483 | DY12: 0.96904762 | DZ12: 1.7833333 | EA12: 0.76061224 | EB12: 1.5048214 | EC12: 0.92877551 | ED12: -8.81 | EE12: 2.86 | EF12: 2.19 | EG12: 0.87 | EH12: 1.76 | EI12: 0.71375 | EJ12: 1.48 | EK12: 0.90333333 | EO12: Error [m] | EP12: 3.35 | EQ12: 5.4824528 | ER12: 3.4726415 | ES12: 3.8245455 | ET12: 3.3821739 | EU12: 1.1197674 | EV12: 3.4629545 | EW12: 0.65234043 | EX12: 3.35 | EY12: 5.4986792 | EZ12: 3.4722222 | FA12: 3.8245455 | FB12: 3.3857447 | FC12: 1.1165909 | FD12: 3.4611111 | FE12: 0.67404255
E13: Error [%] | F13: 1.35 | G13: -8.69 | H13: -1.08 | I13: 5.61 | J13: -3.07 | K13: -8.65 | L13: -11.58 | M13: 6.08 | N13: 1.2672894 | O13: -8.7870247 | P13: -1.048656 | Q13: 7.5990676 | R13: -3.0908326 | S13: -8.8891971 | T13: -11.819343 | U13: 6.8843867 | Y13: Error [%] | Z13: 1.4884553 | AA13: -2.4007465 | AB13: -2.4395798 | AC13: 6.0094902 | AD13: 0.4271476 | AE13: -2.0029832 | AF13: -5.7700512 | AG13: -10.106685 | AH13: 1.5020559 | AI13: -2.6933731 | AJ13: -2.4486856 | AK13: 5.7494959 | AL13: 2.8182702 | AM13: -0.51851359 | AN13: -5.4334301 | AO13: -10.675563 | AS13: Error [%] | AT13: -0.87406505 | AU13: -0.63414929 | AV13: -6.7079632 | AW13: 2.9702593 | AX13: -0.50519919 | AY13: 1.4094905 | AZ13: 5.5714963 | BA13: -8.324195 | BB13: -0.97098152 | BC13: -0.98990589 | BD13: -6.6254113 | BE13: 2.8936417 | BF13: -0.66592675 | BG13: 1.4227366 | BH13: 5.4027014 | BI13: -7.9697698 | BM13: Error [%] | BN13: 1.9324986 | BO13: -0.22733089 | BP13: -3.4973586 | BQ13: 4.8436138 | BR13: 1.0111241 | BS13: -1.4908366 | BT13: 0.95749531 | BU13: -9.003699 | BV13: 1.1122346 | BW13: -0.18941786 | BX13: -3.697792 | BY13: 3.6790592 | BZ13: 0.041283543 | CA13: -1.5010722 | CB13: 0.9170208 | CC13: -9.3870322 | CG13: Error [%] | CH13: 30.96392 | CI13: 251.27506 | CJ13: 104.70416 | CK13: 74.154091 | CL13: 200.73078 | CM13: 158.96728 | CN13: 22.927181 | CO13: -16.472987 | DA13: Error [%] | DB13: 437.3877 | DC13: 38.415373 | DD13: 1454.067 | DE13: 285.353 | DF13: 133.44206 | DG13: 102.13608 | DH13: 313.04348 | DI13: 155.93844 | DJ13: 442.66487 | DK13: 49.157303 | DL13: 1304.3344 | DM13: 285.031 | DN13: 152.67043 | DO13: 93.121693 | DP13: 319.5923 | DQ13: 146.49022 | DU13: Error [%] | DV13: -68.354351 | DW13: 213.84996 | DX13: 191.38936 | DY13: 27.99945 | DZ13: 99.257885 | EA13: 31.568694 | EB13: 699.3361 | EC13: 439.71014 | ED13: -69.424744 | EE13: 208.75912 | EF13: 129.5858 | EG13: 24.438202 | EH13: 96.703297 | EI13: 29.058524 | EJ13: 616.66667 | EK13: 381.69014 | EO13: Error [%] | EP13: 394.11765 | EQ13: 917.4929 | ER13: 2356.5941 | ES13: 249.0823 | ET13: 164.35664 | EU13: 159.91365 | EV13: 1165.7995 | EW13: 29.415715 | EX13: 394.11765 | EY13: 945.89419 | EZ13: 2349.6241 | FA13: 249.0823 | FB13: 164.81616 | FC13: 158.7399 | FD13: 1157.9926 | FE13: 30.6947
D14: 3D Walk | E14: Ground Truth | F14: 2.99 | G14: 4.18 | H14: 5.28 | I14: 5.69 | J14: 4.22 | K14: 4.39 | L14: 1.62 | M14: 2.44 | N14: 2.99 | O14: 4.18 | P14: 5.28 | Q14: 5.69 | R14: 4.22 | S14: 4.39 | T14: 1.62 | U14: 2.44 | X14: 3D Walk | Y14: Ground Truth | Z14: 2.84 | AA14: 5.41 | AB14: 5.1 | AC14: 6.17 | AD14: 5.33 | AE14: 3.65 | AF14: 2.94 | AG14: 3.12 | AH14: 2.84 | AI14: 5.41 | AJ14: 5.1 | AK14: 6.17 | AL14: 5.33 | AM14: 3.65 | AN14: 2.94 | AO14: 3.12 | AR14: 3D Walk | AS14: Ground Truth | AT14: 3.86 | AU14: 4.24 | AV14: 3.37 | AW14: 4.38 | AX14: 3.57 | AY14: 3.19 | AZ14: 1.74 | BA14: 1.12 | BB14: 3.86 | BC14: 4.24 | BD14: 3.37 | BE14: 4.38 | BF14: 3.57 | BG14: 3.19 | BH14: 1.74 | BI14: 1.12 | BL14: 3D Walk | BM14: Ground Truth | BN14: 4.14 | BO14: 6.08 | BP14: 3.66 | BQ14: 5.32 | BR14: 5.44 | BS14: 1.83 | BT14: 3.76 | BU14: 2.91 | BV14: 4.14 | BW14: 6.08 | BX14: 3.66 | BY14: 5.32 | BZ14: 5.44 | CA14: 1.83 | CB14: 3.76 | CC14: 2.91 | CF14: 3D Walk | CG14: Ground Truth | CH14: 2.99 | CI14: 4.18 | CJ14: 5.28 | CK14: 5.69 | CL14: 4.22 | CM14: 4.39 | CN14: 1.62 | CO14: 2.44 | CZ14: 3D Walk | DA14: Ground Truth | DB14: 2.84 | DC14: 5.41 | DD14: 5.1 | DE14: 6.17 | DF14: 5.33 | DG14: 3.65 | DH14: 2.94 | DI14: 3.12 | DJ14: 2.84 | DK14: 5.41 | DL14: 5.1 | DM14: 6.17 | DN14: 5.33 | DO14: 3.65 | DP14: 2.94 | DQ14: 3.12 | DT14: 3D Walk | DU14: Ground Truth | DV14: 3.86 | DW14: 4.24 | DX14: 3.37 | DY14: 4.38 | DZ14: 3.57 | EA14: 3.19 | EB14: 1.74 | EC14: 1.12 | ED14: 3.86 | EE14: 4.24 | EF14: 3.37 | EG14: 4.38 | EH14: 3.57 | EI14: 3.19 | EJ14: 1.74 | EK14: 1.12 | EN14: 3D Walk | EO14: Ground Truth | EP14: 4.14 | EQ14: 6.08 | ER14: 3.66 | ES14: 5.32 | ET14: 5.44 | EU14: 1.83 | EV14: 3.76 | EW14: 2.91 | EX14: 4.14 | EY14: 6.08 | EZ14: 3.66 | FA14: 5.32 | FB14: 5.44 | FC14: 1.83 | FD14: 3.76 | FE14: 2.91
E15: Error [m] | F15: -0.01 | G15: -0.21 | H15: -0.02 | I15: 0.23 | J15: -0.1 | K15: -0.4 | L15: -0.13 | M15: 0.17 | N15: -0.011956522 | O15: -0.21630435 | P15: -0.015531915 | Q15: 0.3275 | R15: -0.10363636 | S15: -0.41733333 | T15: -0.1377551 | U15: 0.18522727 | Y15: Error [m] | Z15: 0.002238806 | AA15: -0.030615385 | AB15: -0.066029412 | AC15: 0.3120339 | AD15: 0.0625 | AE15: -0.074603175 | AF15: -0.084516129 | AG15: -0.28403509 | AH15: 0.0026190476 | AI15: -0.046976744 | AJ15: -0.066511628 | AK15: 0.29763158 | AL15: 0.185 | AM15: -0.01902439 | AN15: -0.07375 | AO15: -0.30571429 | AS15: Error [m] | AT15: -0.054212766 | AU15: -0.016995708 | AV15: -0.78898305 | AW15: 0.077786885 | AX15: -0.028177966 | AY15: 0.064059829 | AZ15: 0.11077236 | BA15: -0.1235124 | BB15: -0.058043478 | BC15: -0.032291667 | BD15: -0.78530612 | BE15: 0.074583333 | BF15: -0.034 | BG15: 0.064468085 | BH15: 0.10816327 | BI15: -0.1187234 | BM15: Error [m] | BN15: 0.019626168 | BO15: -0.013853211 | BP15: -0.091192661 | BQ15: 0.20762376 | BR15: 0.054454545 | BS15: -0.01754386 | BT15: 0.035660377 | BU15: -0.24397436 | BV15: -0.0138 | BW15: -0.011538462 | BX15: -0.099 | BY15: 0.1502 | BZ15: 0.002244898 | CA15: -0.017735849 | CB15: 0.034166667 | CC15: -0.25731707 | CG15: Error [m] | CH15: 0.66875 | CI15: 3.0384444 | CJ15: 2.7202083 | CK15: 2.3768421 | CL15: 2.8267273 | CM15: 2.6986667 | CN15: 0.35909091 | CO15: -0.44529412 | DA15: Error [m] | DB15: 2.3040741 | DC15: 1.5737209 | DD15: 4.7756897 | DE15: 4.5584906 | DF15: 3.063913 | DG15: 1.8442857 | DH15: 2.25 | DI15: 1.9244 | DJ15: 2.3092857 | DK15: 1.85 | DL15: 4.7411111 | DM15: 4.5571429 | DN15: 3.2363636 | DO15: 1.76 | DP15: 2.2607692 | DQ15: 1.8785714 | DU15: Error [m] | DV15: -8.4007692 | DW15: 2.8922222 | DX15: 2.0384483 | DY15: 0.91904762 | DZ15: 1.7733333 | EA15: 0.78061224 | EB15: 1.5248214 | EC15: 0.90877551 | ED15: -8.83 | EE15: 2.87 | EF15: 1.68 | EG15: 0.82 | EH15: 1.75 | EI15: 0.73375 | EJ15: 1.5 | EK15: 0.88333333 | EO15: Error [m] | EP15: 3.29 | EQ15: 5.4824528 | ER15: 3.5126415 | ES15: 3.7845455 | ET15: 3.3821739 | EU15: 1.1297674 | EV15: 3.4629545 | EW15: 0.69234043 | EX15: 3.29 | EY15: 5.4986792 | EZ15: 3.5122222 | FA15: 3.7845455 | FB15: 3.3857447 | FC15: 1.1265909 | FD15: 3.4611111 | FE15: 0.71404255
E16: Error [%] | F16: -0.32 | G16: -4.82 | H16: -0.33 | I16: 4.15 | J16: -2.37 | K16: -8.44 | L16: -7.59 | M16: 7.4 | N16: -0.39829097 | O16: -4.9201404 | P16: -0.29330226 | Q16: 6.1072261 | R16: -2.3969722 | S16: -8.6811815 | T16: -7.8369906 | U16: 8.2148977 | Y16: Error [%] | Z16: 0.078893389 | AA16: -0.56271915 | AB16: -1.2781463 | AC16: 5.3266593 | AD16: 1.1865211 | AE16: -2.0029832 | AF16: -2.7943686 | AG16: -8.3440705 | AH16: 0.09230511 | AI16: -0.86085659 | AJ16: -1.2873605 | AK16: 5.0683397 | AL16: 3.595724 | AM16: -0.51851359 | AN16: -2.4471174 | AO16: -8.9241034 | AS16: Error [%] | AT16: -1.3850235 | AU16: -0.39924184 | AV16: -18.970576 | AW16: 1.8080668 | AX16: -0.78311763 | AY16: 2.049298 | AZ16: 6.7990718 | BA16: -9.9325425 | BB16: -1.4814404 | BC16: -0.75583947 | BD16: -18.898875 | BE16: 1.7323139 | BF16: -0.94339623 | BG16: 2.0626276 | BH16: 6.6283142 | BI16: -9.5843353 | BM16: Error [%] | BN16: 0.47632009 | BO16: -0.22733089 | BP16: -2.4310311 | BQ16: 4.0611988 | BR16: 1.0111241 | BS16: -0.94957744 | BT16: 0.95749531 | BU16: -7.7354579 | BV16: -0.33222591 | BW16: -0.18941786 | BX16: -2.6336792 | BY16: 2.9053348 | BZ16: 0.041283543 | CA16: -0.95986929 | CB16: 0.9170208 | CC16: -8.1241337 | CG16: Error [%] | CH16: 28.809908 | CI16: 266.16702 | CJ16: 106.26679 | CK16: 71.739476 | CL16: 202.88399 | CM16: 159.55853 | CN16: 28.478731 | CO16: -15.433231 | DA16: Error [%] | DB16: 429.92398 | DC16: 41.022066 | DD16: 1472.5678 | DE16: 282.87086 | DF16: 135.20721 | DG16: 102.13608 | DH16: 326.08696 | DI16: 160.95684 | DJ16: 435.12786 | DK16: 51.966292 | DL16: 1321.0526 | DM16: 282.55093 | DN16: 154.58098 | DO16: 93.121693 | DP16: 332.84258 | DQ16: 151.32336 | DU16: Error [%] | DV16: -68.517473 | DW16: 214.59192 | DX16: 153.08818 | DY16: 26.554761 | DZ16: 98.701299 | EA16: 32.39878 | EB16: 708.63071 | EC16: 430.24155 | ED16: -69.582348 | EE16: 209.48905 | EF16: 99.408284 | EG16: 23.033708 | EH16: 96.153846 | EI16: 29.872774 | EJ16: 625 | EK16: 373.23944 | EO16: Error [%] | EP16: 387.05882 | EQ16: 917.4929 | ER16: 2383.7388 | ES16: 246.47721 | ET16: 164.35664 | EU16: 161.34175 | EV16: 1165.7995 | EW16: 31.219419 | EX16: 387.05882 | EY16: 945.89419 | EZ16: 2376.6917 | FA16: 246.47721 | FB16: 164.81616 | FC16: 160.16155 | FD16: 1157.9926 | FE16: 32.516229
D17: 3D Model | E17: Ground Truth | F17: 2.99 | G17: 4.19 | H17: 5.3 | I17: 5.73 | J17: 4.24 | K17: 4.45 | L17: 1.61 | M17: 2.42 | N17: 2.99 | O17: 4.19 | P17: 5.3 | Q17: 5.73 | R17: 4.24 | S17: 4.45 | T17: 1.61 | U17: 2.42 | X17: 3D Model | Y17: Ground Truth | Z17: 2.88 | AA17: 5.38 | AB17: 5.1 | AC17: 6.21 | AD17: 5.33 | AE17: 3.71 | AF17: 2.87 | AG17: 3.05 | AH17: 2.88 | AI17: 5.38 | AJ17: 5.1 | AK17: 6.21 | AL17: 5.33 | AM17: 3.71 | AN17: 2.87 | AO17: 3.05 | AR17: 3D Model | AS17: Ground Truth | AT17: 3.83 | AU17: 4.29 | AV17: 3.95 | AW17: 4.43 | AX17: 3.64 | AY17: 3.23 | AZ17: 1.7 | BA17: 1.13 | BB17: 3.83 | BC17: 4.29 | BD17: 3.95 | BE17: 4.43 | BF17: 3.64 | BG17: 3.23 | BH17: 1.7 | BI17: 1.13 | BL17: 3D Model | BM17: Ground Truth | BN17: 4.19 | BO17: 6.13 | BP17: 3.69 | BQ17: 5.35 | BR17: 5.49 | BS17: 1.85 | BT17: 3.72 | BU17: 2.9 | BV17: 4.19 | BW17: 6.13 | BX17: 3.69 | BY17: 5.35 | BZ17: 5.49 | CA17: 1.85 | CB17: 3.72 | CC17: 2.9 | CF17: 3D Model | CG17: Ground Truth | CH17: 2.99 | CI17: 4.19 | CJ17: 5.3 | CK17: 5.73 | CL17: 4.24 | CM17: 4.45 | CN17: 1.61 | CO17: 2.42 | CZ17: 3D Model | DA17: Ground Truth | DB17: 2.88 | DC17: 5.38 | DD17: 5.1 | DE17: 6.21 | DF17: 5.33 | DG17: 3.71 | DH17: 2.87 | DI17: 3.05 | DJ17: 2.88 | DK17: 5.38 | DL17: 5.1 | DM17: 6.21 | DN17: 5.33 | DO17: 3.71 | DP17: 2.87 | DQ17: 3.05 | DT17: 3D Model | DU17: Ground Truth | DV17: 3.83 | DW17: 4.29 | DX17: 3.95 | DY17: 4.43 | DZ17: 3.64 | EA17: 3.23 | EB17: 1.7 | EC17: 1.13 | ED17: 3.83 | EE17: 4.29 | EF17: 3.95 | EG17: 4.43 | EH17: 3.64 | EI17: 3.23 | EJ17: 1.7 | EK17: 1.13 | EN17: 3D Model | EO17: Ground Truth | EP17: 4.19 | EQ17: 6.13 | ER17: 3.69 | ES17: 5.35 | ET17: 5.49 | EU17: 1.85 | EV17: 3.72 | EW17: 2.9 | EX17: 4.19 | EY17: 6.13 | EZ17: 3.69 | FA17: 5.35 | FB17: 5.49 | FC17: 1.85 | FD17: 3.72 | FE17: 2.9
E18: Error [m] | F18: -0.01 | G18: -0.2 | H18: 0 | I18: 0.27 | J18: -0.08 | K18: -0.34 | L18: -0.14 | M18: 0.15 | N18: -0.011956522 | O18: -0.20630435 | P18: 0.0044680851 | Q18: 0.3675 | R18: -0.083636364 | S18: -0.35733333 | T18: -0.1477551 | U18: 0.16522727 | Y18: Error [m] | Z18: 0.042238806 | AA18: -0.060615385 | AB18: -0.066029412 | AC18: 0.3520339 | AD18: 0.0625 | AE18: -0.014603175 | AF18: -0.15451613 | AG18: -0.35403509 | AH18: 0.042619048 | AI18: -0.076976744 | AJ18: -0.066511628 | AK18: 0.33763158 | AL18: 0.185 | AM18: 0.04097561 | AN18: -0.14375 | AO18: -0.37571429 | AS18: Error [m] | AT18: -0.084212766 | AU18: 0.033004292 | AV18: -0.20898305 | AW18: 0.12778689 | AX18: 0.041822034 | AY18: 0.10405983 | AZ18: 0.070772358 | BA18: -0.1135124 | BB18: -0.088043478 | BC18: 0.017708333 | BD18: -0.20530612 | BE18: 0.12458333 | BF18: 0.036 | BG18: 0.10446809 | BH18: 0.068163265 | BI18: -0.1087234 | BM18: Error [m] | BN18: 0.069626168 | BO18: 0.036146789 | BP18: -0.061192661 | BQ18: 0.23762376 | BR18: 0.10445455 | BS18: 0.0024561404 | BT18: -0.0043396226 | BU18: -0.25397436 | BV18: 0.0362 | BW18: 0.038461538 | BX18: -0.069 | BY18: 0.1802 | BZ18: 0.052244898 | CA18: 0.0022641509 | CB18: -0.0058333333 | CC18: -0.26731707 | CG18: Error [m] | CH18: 0.66875 | CI18: 3.0484444 | CJ18: 2.7402083 | CK18: 2.4168421 | CL18: 2.8467273 | CM18: 2.7586667 | CN18: 0.34909091 | CO18: -0.46529412 | DA18: Error [m] | DB18: 2.3440741 | DC18: 1.5437209 | DD18: 4.7756897 | DE18: 4.5984906 | DF18: 3.063913 | DG18: 1.9042857 | DH18: 2.18 | DI18: 1.8544 | DJ18: 2.3492857 | DK18: 1.82 | DL18: 4.7411111 | DM18: 4.5971429 | DN18: 3.2363636 | DO18: 1.82 | DP18: 2.1907692 | DQ18: 1.8085714 | DU18: Error [m] | DV18: -8.4307692 | DW18: 2.9422222 | DX18: 2.6184483 | DY18: 0.96904762 | DZ18: 1.8433333 | EA18: 0.82061224 | EB18: 1.4848214 | EC18: 0.91877551 | ED18: -8.86 | EE18: 2.92 | EF18: 2.26 | EG18: 0.87 | EH18: 1.82 | EI18: 0.77375 | EJ18: 1.46 | EK18: 0.89333333 | EO18: Error [m] | EP18: 3.34 | EQ18: 5.5324528 | ER18: 3.5426415 | ES18: 3.8145455 | ET18: 3.4321739 | EU18: 1.1497674 | EV18: 3.4229545 | EW18: 0.68234043 | EX18: 3.34 | EY18: 5.5486792 | EZ18: 3.5422222 | FA18: 3.8145455 | FB18: 3.4357447 | FC18: 1.1465909 | FD18: 3.4211111 | FE18: 0.70404255
E19: Error [%] | F19: -0.32 | G19: -4.59 | H19: 0.05 | I19: 4.88 | J19: -1.91 | K19: -7.19 | L19: -8.16 | M19: 6.52 | N19: -0.39829097 | O19: -4.6926767 | P19: 0.084374623 | Q19: 6.8531469 | R19: -1.9343987 | S19: -7.4330883 | T19: -8.4058981 | U19: 7.3278903 | Y19: Error [%] | Z19: 1.4884553 | AA19: -1.1141274 | AB19: -1.2781463 | AC19: 6.0094902 | AD19: 1.1865211 | AE19: -0.3920733 | AF19: -5.1087884 | AG19: -10.400454 | AH19: 1.5020559 | AI19: -1.4106115 | AJ19: -1.2873605 | AK19: 5.7494959 | AL19: 3.595724 | AM19: 1.1167985 | AN19: -4.7698051 | AO19: -10.967473 | AS19: Error [%] | AT19: -2.1514611 | AU19: 0.7752954 | AV19: -5.0248594 | AW19: 2.9702593 | AX19: 1.1623114 | AY19: 3.328913 | AZ19: 4.3439208 | BA19: -9.1283687 | BB19: -2.2471287 | BC19: 0.41449261 | BD19: -4.9408182 | BE19: 2.8936417 | BF19: 0.99889012 | BG19: 3.3424098 | BH19: 4.1770885 | BI19: -8.7770526 | BM19: Error [%] | BN19: 1.6898022 | BO19: 0.59316803 | BP19: -1.6312855 | BQ19: 4.6480101 | BR19: 1.9395351 | BS19: 0.13294084 | BT19: -0.11652059 | BU19: -8.0525182 | BV19: 0.87149116 | BW19: 0.63139285 | BX19: -1.8355946 | BY19: 3.4856281 | BZ19: 0.96078063 | CA19: 0.12253651 | CB19: -0.15656453 | CC19: -8.4398583 | CG19: Error [%] | CH19: 28.809908 | CI19: 267.04302 | CJ19: 107.0481 | CK19: 72.946783 | CL19: 204.31946 | CM19: 163.10603 | CN19: 27.685652 | CO19: -16.126402 | DA19: Error [%] | DB19: 437.3877 | DC19: 40.240058 | DD19: 1472.5678 | DE19: 285.353 | DF19: 135.20721 | DG19: 105.45886 | DH19: 315.94203 | DI19: 155.10204 | DJ19: 442.66487 | DK19: 51.123596 | DL19: 1321.0526 | DM19: 285.031 | DN19: 154.58098 | DO19: 96.296296 | DP19: 322.53681 | DQ19: 145.6847 | DU19: Error [%] | DV19: -68.762156 | DW19: 218.30173 | DX19: 196.64638 | DY19: 27.99945 | DZ19: 102.5974 | EA19: 34.058953 | EB19: 690.04149 | EC19: 434.97585 | ED19: -69.818755 | EE19: 213.13869 | EF19: 133.72781 | EG19: 24.438202 | EH19: 100 | EI19: 31.501272 | EJ19: 608.33333 | EK19: 377.46479 | EO19: Error [%] | EP19: 392.94118 | EQ19: 925.86044 | ER19: 2404.0973 | ES19: 248.43102 | ET19: 166.78639 | EU19: 164.19794 | EV19: 1152.3336 | EW19: 30.768493 | EX19: 392.94118 | EY19: 954.49529 | EZ19: 2396.9925 | FA19: 248.43102 | FB19: 167.25013 | FC19: 163.00485 | FD19: 1144.6097 | FE19: 32.060847
C20: 2 | D20: Mean unfiltered value | F20: 2.9588571 | G20: 4.3125309 | H20: 5.0741954 | I20: 5.094375 | J20: 4.228125 | K20: 4.4652273 | L20: 1.7498851 | M20: 2.2560227 | N20: 2.8634091 | O20: 4.3536585 | P20: 5.0059091 | Q20: 4.9744444 | R20: 4.0955556 | S20: 4.3077778 | T20: 1.7532558 | U20: 2.2702222 | W20: 2 | X20: Mean unfiltered value | Z20: 2.7745833 | AA20: 5.3409722 | AB20: 4.9484848 | AC20: 5.3477778 | AD20: 4.9492308 | AE20: 3.5276389 | AF20: 2.8105556 | AG20: 3.3192647 | AH20: 2.77 | AI20: 5.3922222 | AJ20: 4.8702381 | AK20: 5.3264444 | AL20: 4.586 | AM20: 3.5191111 | AN20: 2.7386667 | AO20: 3.3268293 | AQ20: 2 | AR20: Mean unfiltered value | AT20: 3.7704167 | AU20: 3.9838636 | AV20: 3.9887879 | AW20: 4.1714559 | AX20: 3.3225 | AY20: 3.0324715 | AZ20: 1.5715152 | BA20: 1.2284351 | BB20: 3.7566 | BC20: 3.7964 | BD20: 3.993 | BE20: 4.1602083 | BF20: 3.2242 | BG20: 3.0856 | BH20: 1.5656 | BI20: 1.2342 | BK20: 2 | BL20: Mean unfiltered value | BN20: 4.0042017 | BO20: 5.9033913 | BP20: 3.6985714 | BQ20: 4.8133051 | BR20: 5.0250847 | BS20: 1.8402521 | BT20: 3.6768908 | BU20: 3.0604255 | BV20: 4.0416 | BW20: 5.8229167 | BX20: 3.6996 | BY20: 4.7832653 | BZ20: 4.935102 | CA20: 1.846 | CB20: 3.7338 | CC20: 2.9737143 | CE20: 2 | CF20: Mean unfiltered value | CH20: 3.6758491 | CI20: 1.2244737 | CJ20: 3.0998077 | CK20: 3.9335593 | CL20: 1.5937931 | CM20: 8.075 | CN20: 1.0561404 | CO20: 3.4342857 | CP20: 3.2601852 | CQ20: 1.2107895 | CR20: 3.0053846 | CS20: 3.9521667 | CT20: 1.59 | CU20: 7.1284314 | CV20: 1.07 | CW20: 3.525 | CY20: 2 | CZ20: Mean unfiltered value | DB20: 0.55155172 | DC20: 3.2267797 | DD20: 0.4059322 | DE20: 1.8638983 | DF20: 5.1486441 | DG20: 2.249322 | DH20: 0.67711864 | DI20: 1.38 | DJ20: 0.55530612 | DK20: 3.2304 | DL20: 0.4184 | DM20: 1.8706 | DN20: 5.6768 | DO20: 2.2054 | DP20: 0.6742 | DQ20: 1.4078261 | DS20: 2 | DT20: Mean unfiltered value | DV20: 12.484915 | DW20: 1.3778571 | DX20: 1.6754237 | DY20: 3.1871429 | DZ20: 1.6886441 | EA20: 2.65 | EB20: 0.22050847 | EC20: 0.33186441 | ED20: 12.6406 | EE20: 1.3726087 | EF20: 1.6712 | EG20: 3.1044681 | EH20: 1.678 | EI20: 2.6764 | EJ20: 0.217 | EK20: 0.3362 | EM20: 2 | EN20: Mean unfiltered value | EP20: 0.82153846 | EQ20: 1.1481356 | ER20: 0.14932203 | ES20: 2.1712 | ET20: 1.8248148 | EU20: 0.61508475 | EV20: 0.30949153 | EW20: 2.4864407 | EX20: 0.81814815 | EY20: 1.1245 | EZ20: 0.14933333 | FA20: 2.2538 | FB20: 1.8616364 | FC20: 0.61966667 | FD20: 0.30933333 | FE20: 2.5141667
D21: Standard deviation | F21: 0.32759358 | G21: 0.42500299 | H21: 0.85627178 | I21: 1.244369 | J21: 0.4803046 | K21: 0.94481056 | L21: 0.02465832 | M21: 0.51525708 | N21: 0.60566621 | O21: 0.21854012 | P21: 0.98869362 | Q21: 1.3668025 | R21: 0.76040503 | S21: 1.0298865 | T21: 0.021210016 | U21: 0.48472438 | X21: Standard deviation | Z21: 0.22959468 | AA21: 0.48153158 | AB21: 0.81380372 | AC21: 1.3269841 | AD21: 0.7644753 | AE21: 0.62542095 | AF21: 0.74759223 | AG21: 0.60423582 | AH21: 0.23716848 | AI21: 0.39795527 | AJ21: 0.94582916 | AK21: 1.3089235 | AL21: 1.1380088 | AM21: 0.71370651 | AN21: 0.83069342 | AO21: 0.63476302 | AR21: Standard deviation | AT21: 0.61348808 | AU21: 0.85193421 | AV21: 0.63188215 | AW21: 0.62397209 | AX21: 0.79366562 | AY21: 0.46321284 | AZ21: 0.26269 | BA21: 0.14132765 | BB21: 0.64714947 | BC21: 1.1260049 | BD21: 0.61632865 | BE21: 0.68147967 | BF21: 0.88550119 | BG21: 0.25582932 | BH21: 0.27568214 | BI21: 0.092673405 | BL21: Standard deviation | BN21: 0.63082645 | BO21: 0.88432228 | BP21: 0.39558124 | BQ21: 1.1169276 | BR21: 1.1022717 | BS21: 0.066313011 | BT21: 0.46479371 | BU21: 0.59666434 | BV21: 0.51851079 | BW21: 1.0088916 | BX21: 0.27740916 | BY21: 1.2196945 | BZ21: 1.1146137 | CA21: 0.015491933 | CB21: 0.16877073 | CC21: 0.64843586 | CF21: Standard deviation | CH21: 4.7397705 | CI21: 0.38735743 | CJ21: 2.0440246 | CK21: 2.7660728 | CL21: 0.97513364 | CM21: 20.958794 | CN21: 0.37503101 | CO21: 1.7220353 | CP21: 3.7826468 | CQ21: 0.30504859 | CR21: 1.8321409 | CS21: 2.7362158 | CT21: 0.96726594 | CU21: 19.718178 | CV21: 0.35583317 | CW21: 1.6961618 | CZ21: Standard deviation | DB21: 0.095841135 | DC21: 1.7154625 | DD21: 0.59528976 | DE21: 0.66507809 | DF21: 6.2624887 | DG21: 1.5230855 | DH21: 0.064283557 | DI21: 0.74407785 | DJ21: 0.10240181 | DK21: 1.7498697 | DL21: 0.64447299 | DM21: 0.67383502 | DN21: 6.6628914 | DO21: 1.4385718 | DP21: 0.065851044 | DQ21: 0.80212737 | DT21: Standard deviation | DV21: 2.5791954 | DW21: 0.22429823 | DX21: 1.6750789 | DY21: 0.70117176 | DZ21: 0.22361785 | EA21: 0.71844701 | EB21: 0.027826565 | EC21: 0.18387979 | ED21: 2.1027377 | EE21: 0.21771975 | EF21: 1.8180557 | EG21: 0.77825721 | EH21: 0.22 | EI21: 0.69138053 | EJ21: 0.031064449 | EK21: 0.18272263 | EN21: Standard deviation | EP21: 0.07289045 | EQ21: 1.9353005 | ER21: 0.027050762 | ES21: 2.1506033 | ET21: 0.46566854 | EU21: 0.17249292 | EV21: 0.057206842 | EW21: 0.6302159 | EX21: 0.073587289 | EY21: 1.9231861 | EZ21: 0.026824533 | FA21: 2.242453 | FB21: 0.44598721 | FC21: 0.16888819 | FD21: 0.059325842 | FE21: 0.65507071
D22: Mean filtered value | F22: 3 | G22: 4.39 | H22: 5.28 | I22: 5.46 | J22: 4.32 | K22: 4.78 | L22: 1.75 | M22: 2.28 | N22: 2.9954762 | O22: 4.388 | P22: 5.2568293 | Q22: 5.4115 | R22: 4.3095122 | S22: 4.6574359 | T22: 1.7515385 | U22: 2.2935135 | X22: Mean filtered value | Z22: 2.8431818 | AA22: 5.4513235 | AB22: 5.1795082 | AC22: 5.8268852 | AD22: 5.1691667 | AE22: 3.7189231 | AF22: 3.0503077 | AG22: 3.3993333 | AH22: 2.8431707 | AI22: 5.4518182 | AJ22: 5.1765789 | AK22: 5.7505128 | AL22: 5.155 | AM22: 3.7083333 | AN22: 3.0553846 | AO22: 3.4135135 | AR22: Mean filtered value | AT22: 3.9152016 | AU22: 4.2516456 | AV22: 4.1533607 | AW22: 4.2990763 | AX22: 3.5863404 | AY22: 3.1254 | AZ22: 1.6286 | BA22: 1.2496063 | BB22: 3.9197872 | BC22: 4.267619 | BD22: 4.1591304 | BE22: 4.3021739 | BF22: 3.6011905 | BG22: 3.1220408 | BH22: 1.6278723 | BI22: 1.2467347 | BL22: Mean filtered value | BN22: 4.1494643 | BO22: 6.0976147 | BP22: 3.7673684 | BQ22: 5.1278095 | BR22: 5.3187037 | BS22: 1.8461864 | BT22: 3.7506087 | BU22: 3.1469767 | BV22: 4.145 | BW22: 6.0993182 | BX22: 3.7676087 | BY22: 5.1353488 | BZ22: 5.2997674 | CA22: 1.8472727 | CB22: 3.7577551 | CC22: 3.1324242 | CF22: Mean filtered value | CH22: 2.3497959 | CI22: 1.1613514 | CJ22: 2.5554545 | CK22: 3.3019643 | CL22: 1.4107143 | CM22: 1.3395745 | CN22: 1.2245455 | CO22: 2.9807143 | CP22: 2.3592157 | CQ22: 1.17 | CR22: 2.5569565 | CS22: 3.3326316 | CT22: 1.41 | CU22: 1.4619149 | CV22: 1.2178261 | CW22: 2.9485714 | CZ22: Mean filtered value | DB22: 0.5534 | DC22: 4.1736585 | DD22: 0.32862069 | DE22: 1.6060784 | DF22: 2.3361224 | DG22: 1.8398182 | DH22: 0.68368421 | DI22: 1.2013725 | DJ22: 0.55571429 | DK22: 4.2088235 | DL22: 0.32714286 | DM22: 1.6053488 | DN22: 2.3635 | DO22: 1.8431915 | DP22: 0.681875 | DQ22: 1.197907 | DT22: Mean filtered value | DV22: 13.442609 | DW22: 1.3578788 | DX22: 1.3821053 | DY22: 3.5104762 | DZ22: 1.77 | EA22: 2.4559524 | EB22: 0.22857143 | EC22: 0.23372093 | ED22: 12.285652 | EE22: 1.3557143 | EF22: 1.3227083 | EG22: 3.5096774 | EH22: 1.7602439 | EI22: 2.4316667 | EJ22: 0.22947368 | EK22: 0.22971429 | EN22: Mean filtered value | EP22: 0.85 | EQ22: 0.56777778 | ER22: 0.14888889 | ES22: 1.5767391 | ET22: 2.0197778 | EU22: 0.69285714 | EV22: 0.30142857 | EW22: 2.2420408 | EX22: 0.85 | EY22: 0.55254545 | EZ22: 0.14890909 | FA22: 1.5542222 | FB22: 2.0338298 | FC22: 0.70090909 | FD22: 0.30142857 | FE22: 2.226875
D23: Laser | E23: Ground Truth | F23: 3.04 | G23: 4.01 | H23: 5.24 | I23: 5.77 | J23: 4.19 | K23: 4.38 | L23: 1.55 | M23: 2.41 | N23: 3.04 | O23: 4.01 | P23: 5.24 | Q23: 5.77 | R23: 4.19 | S23: 4.38 | T23: 1.55 | U23: 2.41 | X23: Laser | Y23: Ground Truth | Z23: 2.88 | AA23: 5.31 | AB23: 5.04 | AC23: 6.21 | AD23: 5.29 | AE23: 3.65 | AF23: 2.85 | AG23: 3.06 | AH23: 2.88 | AI23: 5.31 | AJ23: 5.04 | AK23: 6.21 | AL23: 5.29 | AM23: 3.65 | AN23: 2.85 | AO23: 3.06 | AR23: Laser | AS23: Ground Truth | AT23: 3.88 | AU23: 4.23 | AV23: 3.88 | AW23: 4.43 | AX23: 3.58 | AY23: 3.17 | AZ23: 1.72 | BA23: 1.14 | BB23: 3.88 | BC23: 4.23 | BD23: 3.88 | BE23: 4.43 | BF23: 3.58 | BG23: 3.17 | BH23: 1.72 | BI23: 1.14 | BL23: Laser | BM23: Ground Truth | BN23: 4.2 | BO23: 6.08 | BP23: 3.62 | BQ23: 5.36 | BR23: 5.44 | BS23: 1.82 | BT23: 3.76 | BU23: 2.87 | BV23: 4.2 | BW23: 6.08 | BX23: 3.62 | BY23: 5.36 | BZ23: 5.44 | CA23: 1.82 | CB23: 3.76 | CC23: 2.87 | CF23: Laser | CG23: Ground Truth | CH23: 3.04 | CI23: 4.01 | CJ23: 5.24 | CK23: 5.77 | CL23: 4.19 | CM23: 4.38 | CN23: 1.55 | CO23: 2.41 | CP23: 3.04 | CQ23: 4.01 | CR23: 5.24 | CS23: 5.77 | CT23: 4.19 | CU23: 4.38 | CV23: 1.55 | CW23: 2.41 | CZ23: Laser | DA23: Ground Truth | DB23: 2.88 | DC23: 5.31 | DD23: 5.04 | DE23: 6.21 | DF23: 5.29 | DG23: 3.65 | DH23: 2.85 | DI23: 3.06 | DJ23: 2.88 | DK23: 5.31 | DL23: 5.04 | DM23: 6.21 | DN23: 5.29 | DO23: 3.65 | DP23: 2.85 | DQ23: 3.06 | DT23: Laser | DU23: Ground Truth | DV23: 3.88 | DW23: 4.23 | DX23: 3.88 | DY23: 4.43 | DZ23: 3.58 | EA23: 3.17 | EB23: 1.72 | EC23: 1.14 | ED23: 3.88 | EE23: 4.23 | EF23: 3.88 | EG23: 4.43 | EH23: 3.58 | EI23: 3.17 | EJ23: 1.72 | EK23: 1.14 | EN23: Laser | EO23: Ground Truth | EP23: 4.2 | EQ23: 6.08 | ER23: 3.62 | ES23: 5.36 | ET23: 5.44 | EU23: 1.82 | EV23: 3.76 | EW23: 2.87 | EX23: 4.2 | EY23: 6.08 | EZ23: 3.62 | FA23: 5.36 | FB23: 5.44 | FC23: 1.82 | FD23: 3.76 | FE23: 2.87
E24: Error [m] | F24: 0.04 | G24: -0.38 | H24: -0.04 | I24: 0.31 | J24: -0.13 | K24: -0.4 | L24: -0.2 | M24: 0.13 | N24: 0.04452381 | O24: -0.378 | P24: -0.016829268 | Q24: 0.3585 | R24: -0.1195122 | S24: -0.2774359 | T24: -0.20153846 | U24: 0.11648649 | Y24: Error [m] | Z24: 0.036818182 | AA24: -0.14132353 | AB24: -0.1395082 | AC24: 0.38311475 | AD24: 0.12083333 | AE24: -0.068923077 | AF24: -0.20030769 | AG24: -0.33933333 | AH24: 0.036829268 | AI24: -0.14181818 | AJ24: -0.13657895 | AK24: 0.45948718 | AL24: 0.135 | AM24: -0.058333333 | AN24: -0.20538462 | AO24: -0.35351351 | AS24: Error [m] | AT24: -0.035201613 | AU24: -0.02164557 | AV24: -0.27336066 | AW24: 0.13092369 | AX24: -0.0063404255 | AY24: 0.0446 | AZ24: 0.0914 | BA24: -0.1096063 | BB24: -0.039787234 | BC24: -0.037619048 | BD24: -0.27913043 | BE24: 0.12782609 | BF24: -0.021190476 | BG24: 0.047959184 | BH24: 0.09212766 | BI24: -0.10673469 | BM24: Error [m] | BN24: 0.050535714 | BO24: -0.017614679 | BP24: -0.14736842 | BQ24: 0.23219048 | BR24: 0.1212963 | BS24: -0.026186441 | BT24: 0.0093913043 | BU24: -0.27697674 | BV24: 0.055 | BW24: -0.019318182 | BX24: -0.1476087 | BY24: 0.22465116 | BZ24: 0.14023256 | CA24: -0.027272727 | CB24: 0.002244898 | CC24: -0.26242424 | CG24: Error [m] | CH24: 0.69020408 | CI24: 2.8486486 | CJ24: 2.6845455 | CK24: 2.4680357 | CL24: 2.7792857 | CM24: 3.0404255 | CN24: 0.32545455 | CO24: -0.57071429 | CP24: 0.68078431 | CQ24: 2.84 | CR24: 2.6830435 | CS24: 2.4373684 | CT24: 2.78 | CU24: 2.9180851 | CV24: 0.33217391 | CW24: -0.53857143 | DA24: Error [m] | DB24: 2.3266 | DC24: 1.1363415 | DD24: 4.7113793 | DE24: 4.6039216 | DF24: 2.9538776 | DG24: 1.8101818 | DH24: 2.1663158 | DI24: 1.8586275 | DJ24: 2.3242857 | DK24: 1.1011765 | DL24: 4.7128571 | DM24: 4.6046512 | DN24: 2.9265 | DO24: 1.8068085 | DP24: 2.168125 | DQ24: 1.862093 | DU24: Error [m] | DV24: -9.5626087 | DW24: 2.8721212 | DX24: 2.4978947 | DY24: 0.91952381 | DZ24: 1.81 | EA24: 0.71404762 | EB24: 1.4914286 | EC24: 0.90627907 | ED24: -8.4056522 | EE24: 2.8742857 | EF24: 2.5572917 | EG24: 0.92032258 | EH24: 1.8197561 | EI24: 0.73833333 | EJ24: 1.4905263 | EK24: 0.91028571 | EO24: Error [m] | EP24: 3.35 | EQ24: 5.5122222 | ER24: 3.4711111 | ES24: 3.7832609 | ET24: 3.4202222 | EU24: 1.1271429 | EV24: 3.4585714 | EW24: 0.62795918 | EX24: 3.35 | EY24: 5.5274545 | EZ24: 3.4710909 | FA24: 3.8057778 | FB24: 3.4061702 | FC24: 1.1190909 | FD24: 3.4585714 | FE24: 0.643125
E25: Error [%] | F25: 1.32 | G25: -8.56 | H25: -0.69 | I25: 5.72 | J25: -3.08 | K25: -8.43 | L25: -11.39 | M25: 5.93 | N25: 1.4863683 | O25: -8.6144029 | P25: -0.32014105 | Q25: 6.6247806 | R25: -2.7732186 | S25: -5.9568377 | T25: -11.506368 | U25: 5.0789536 | Y25: Error [%] | Z25: 1.294964 | AA25: -2.5924627 | AB25: -2.6934642 | AC25: 6.5749494 | AD25: 2.3375786 | AE25: -1.8533074 | AF25: -6.5668028 | AG25: -9.9823495 | AH25: 1.295359 | AI25: -2.6013007 | AJ25: -2.6384017 | AK25: 7.9903688 | AL25: 2.6188167 | AM25: -1.5730337 | AN25: -6.7220544 | AO25: -10.356295 | AS25: Error [%] | AT25: -0.8991009 | AU25: -0.5091104 | AV25: -6.5816739 | AW25: 3.0453913 | AX25: -0.17679374 | AY25: 1.4270173 | AZ25: 5.6121822 | BA25: -8.7712665 | BB25: -1.0150356 | BC25: -0.88149967 | BD25: -6.7112691 | BE25: 2.9711976 | BF25: -0.58842975 | BG25: 1.5361485 | BH25: 5.6593909 | BI25: -8.5611393 | BM25: Error [%] | BN25: 1.2178853 | BO25: -0.28887819 | BP25: -3.9117072 | BQ25: 4.5280636 | BR25: 2.2805613 | BS25: -1.4184072 | BT25: 0.25039414 | BU25: -8.8013597 | BV25: 1.3268999 | BW25: -0.31672691 | BX25: -3.9178351 | BY25: 4.3746037 | BZ25: 2.6460134 | CA25: -1.476378 | CB25: 0.059740401 | CC25: -8.3776724 | CG25: Error [%] | CH25: 29.372937 | CI25: 245.28741 | CJ25: 105.05158 | CK25: 74.74447 | CL25: 197.01266 | CM25: 226.9695 | CN25: 26.57758 | CO25: -19.146897 | CP25: 28.856383 | CQ25: 242.73504 | CR25: 104.93113 | CS25: 73.13645 | CT25: 197.16312 | CU25: 199.60704 | CV25: 27.275973 | CW25: -18.265504 | DA25: Error [%] | DB25: 420.41923 | DC25: 27.226508 | DD25: 1433.6831 | DE25: 286.65609 | DF25: 126.44361 | DG25: 98.389169 | DH25: 316.85912 | DI25: 154.70867 | DJ25: 418.25193 | DK25: 26.163522 | DL25: 1440.6114 | DM25: 286.83181 | DN25: 123.82061 | DO25: 98.026088 | DP25: 317.96517 | DQ25: 155.44554 | DU25: Error [%] | DV25: -71.136555 | DW25: 211.51529 | DX25: 180.73115 | DY25: 26.193706 | DZ25: 102.25989 | EA25: 29.074164 | EB25: 652.5 | EC25: 387.76119 | ED25: -68.418445 | EE25: 212.01264 | EF25: 193.33753 | EG25: 26.222426 | EH25: 103.38091 | EI25: 30.363263 | EJ25: 649.54128 | EK25: 396.26866 | EO25: Error [%] | EP25: 394.11765 | EQ25: 970.84149 | ER25: 2331.3433 | ES25: 239.94209 | ET25: 169.33656 | EU25: 162.68041 | EV25: 1147.3934 | EW25: 28.008374 | EX25: 394.11765 | EY25: 1000.362 | EZ25: 2331.0134 | FA25: 244.86703 | FB25: 167.47568 | FC25: 159.66278 | FD25: 1147.3934 | FE25: 28.880157
D26: 3D Walk | E26: Ground Truth | F26: 2.99 | G26: 4.18 | H26: 5.28 | I26: 5.69 | J26: 4.22 | K26: 4.39 | L26: 1.62 | M26: 2.44 | N26: 2.99 | O26: 4.18 | P26: 5.28 | Q26: 5.69 | R26: 4.22 | S26: 4.39 | T26: 1.62 | U26: 2.44 | X26: 3D Walk | Y26: Ground Truth | Z26: 2.84 | AA26: 5.41 | AB26: 5.1 | AC26: 6.17 | AD26: 5.33 | AE26: 3.65 | AF26: 2.94 | AG26: 3.12 | AH26: 2.84 | AI26: 5.41 | AJ26: 5.1 | AK26: 6.17 | AL26: 5.33 | AM26: 3.65 | AN26: 2.94 | AO26: 3.12 | AR26: 3D Walk | AS26: Ground Truth | AT26: 3.86 | AU26: 4.24 | AV26: 3.37 | AW26: 4.38 | AX26: 3.57 | AY26: 3.19 | AZ26: 1.74 | BA26: 1.12 | BB26: 3.86 | BC26: 4.24 | BD26: 3.37 | BE26: 4.38 | BF26: 3.57 | BG26: 3.19 | BH26: 1.74 | BI26: 1.12 | BL26: 3D Walk | BM26: Ground Truth | BN26: 4.14 | BO26: 6.08 | BP26: 3.66 | BQ26: 5.32 | BR26: 5.44 | BS26: 1.83 | BT26: 3.76 | BU26: 2.91 | BV26: 4.14 | BW26: 6.08 | BX26: 3.66 | BY26: 5.32 | BZ26: 5.44 | CA26: 1.83 | CB26: 3.76 | CC26: 2.91 | CF26: 3D Walk | CG26: Ground Truth | CH26: 2.99 | CI26: 4.18 | CJ26: 5.28 | CK26: 5.69 | CL26: 4.22 | CM26: 4.39 | CN26: 1.62 | CO26: 2.44 | CP26: 2.99 | CQ26: 4.18 | CR26: 5.28 | CS26: 5.69 | CT26: 4.22 | CU26: 4.39 | CV26: 1.62 | CW26: 2.44 | CZ26: 3D Walk | DA26: Ground Truth | DB26: 2.84 | DC26: 5.41 | DD26: 5.1 | DE26: 6.17 | DF26: 5.33 | DG26: 3.65 | DH26: 2.94 | DI26: 3.12 | DJ26: 2.84 | DK26: 5.41 | DL26: 5.1 | DM26: 6.17 | DN26: 5.33 | DO26: 3.65 | DP26: 2.94 | DQ26: 3.12 | DT26: 3D Walk | DU26: Ground Truth | DV26: 3.86 | DW26: 4.24 | DX26: 3.37 | DY26: 4.38 | DZ26: 3.57 | EA26: 3.19 | EB26: 1.74 | EC26: 1.12 | ED26: 3.86 | EE26: 4.24 | EF26: 3.37 | EG26: 4.38 | EH26: 3.57 | EI26: 3.19 | EJ26: 1.74 | EK26: 1.12 | EN26: 3D Walk | EO26: Ground Truth | EP26: 4.14 | EQ26: 6.08 | ER26: 3.66 | ES26: 5.32 | ET26: 5.44 | EU26: 1.83 | EV26: 3.76 | EW26: 2.91 | EX26: 4.14 | EY26: 6.08 | EZ26: 3.66 | FA26: 5.32 | FB26: 5.44 | FC26: 1.83 | FD26: 3.76 | FE26: 2.91
E27: Error [m] | F27: -0.01 | G27: -0.21 | H27: 0 | I27: 0.23 | J27: -0.1 | K27: -0.39 | L27: -0.13 | M27: 0.16 | N27: -0.0054761905 | O27: -0.208 | P27: 0.023170732 | Q27: 0.2785 | R27: -0.089512195 | S27: -0.2674359 | T27: -0.13153846 | U27: 0.14648649 | Y27: Error [m] | Z27: -0.0031818182 | AA27: -0.041323529 | AB27: -0.079508197 | AC27: 0.34311475 | AD27: 0.16083333 | AE27: -0.068923077 | AF27: -0.11030769 | AG27: -0.27933333 | AH27: -0.0031707317 | AI27: -0.041818182 | AJ27: -0.076578947 | AK27: 0.41948718 | AL27: 0.175 | AM27: -0.058333333 | AN27: -0.11538462 | AO27: -0.29351351 | AS27: Error [m] | AT27: -0.055201613 | AU27: -0.01164557 | AV27: -0.78336066 | AW27: 0.080923695 | AX27: -0.016340426 | AY27: 0.0646 | AZ27: 0.1114 | BA27: -0.1296063 | BB27: -0.059787234 | BC27: -0.027619048 | BD27: -0.78913043 | BE27: 0.077826087 | BF27: -0.031190476 | BG27: 0.067959184 | BH27: 0.11212766 | BI27: -0.12673469 | BM27: Error [m] | BN27: -0.0094642857 | BO27: -0.017614679 | BP27: -0.10736842 | BQ27: 0.19219048 | BR27: 0.1212963 | BS27: -0.016186441 | BT27: 0.0093913043 | BU27: -0.23697674 | BV27: -0.005 | BW27: -0.019318182 | BX27: -0.1076087 | BY27: 0.18465116 | BZ27: 0.14023256 | CA27: -0.017272727 | CB27: 0.002244898 | CC27: -0.22242424 | CG27: Error [m] | CH27: 0.64020408 | CI27: 3.0186486 | CJ27: 2.7245455 | CK27: 2.3880357 | CL27: 2.8092857 | CM27: 3.0504255 | CN27: 0.39545455 | CO27: -0.54071429 | CP27: 0.63078431 | CQ27: 3.01 | CR27: 2.7230435 | CS27: 2.3573684 | CT27: 2.81 | CU27: 2.9280851 | CV27: 0.40217391 | CW27: -0.50857143 | DA27: Error [m] | DB27: 2.2866 | DC27: 1.2363415 | DD27: 4.7713793 | DE27: 4.5639216 | DF27: 2.9938776 | DG27: 1.8101818 | DH27: 2.2563158 | DI27: 1.9186275 | DJ27: 2.2842857 | DK27: 1.2011765 | DL27: 4.7728571 | DM27: 4.5646512 | DN27: 2.9665 | DO27: 1.8068085 | DP27: 2.258125 | DQ27: 1.922093 | DU27: Error [m] | DV27: -9.5826087 | DW27: 2.8821212 | DX27: 1.9878947 | DY27: 0.86952381 | DZ27: 1.8 | EA27: 0.73404762 | EB27: 1.5114286 | EC27: 0.88627907 | ED27: -8.4256522 | EE27: 2.8842857 | EF27: 2.0472917 | EG27: 0.87032258 | EH27: 1.8097561 | EI27: 0.75833333 | EJ27: 1.5105263 | EK27: 0.89028571 | EO27: Error [m] | EP27: 3.29 | EQ27: 5.5122222 | ER27: 3.5111111 | ES27: 3.7432609 | ET27: 3.4202222 | EU27: 1.1371429 | EV27: 3.4585714 | EW27: 0.66795918 | EX27: 3.29 | EY27: 5.5274545 | EZ27: 3.5110909 | FA27: 3.7657778 | FB27: 3.4061702 | FC27: 1.1290909 | FD27: 3.4585714 | FE27: 0.683125
E28: Error [%] | F28: -0.34 | G28: -4.68 | H28: 0.06 | I28: 4.25 | J28: -2.39 | K28: -8.22 | L28: -7.39 | M28: 7.25 | N28: -0.18281536 | O28: -4.7402005 | P28: 0.44077391 | Q28: 5.1464474 | R28: -2.0770842 | S28: -5.7421273 | T28: -7.5098814 | U28: 6.3869903 | Y28: Error [%] | Z28: -0.11191047 | AA28: -0.75804581 | AB28: -1.535053 | AC28: 5.8884763 | AD28: 3.1113977 | AE28: -1.8533074 | AF28: -3.6162808 | AG28: -8.2172975 | AH28: -0.11152097 | AI28: -0.76705019 | AJ28: -1.4793351 | AK28: 7.2947786 | AL28: 3.3947624 | AM28: -1.5730337 | AN28: -3.776435 | AO28: -8.5985748 | AS28: Error [%] | AT28: -1.4099303 | AU28: -0.27390735 | AV28: -18.860887 | AW28: 1.8823507 | AX28: -0.45562952 | AY28: 2.0669354 | AZ28: 6.8402309 | BA28: -10.371771 | BB28: -1.5252673 | BC28: -0.64717697 | BD28: -18.973448 | BE28: 1.8089944 | BF28: -0.8661157 | BG28: 2.1767551 | BH28: 6.8879885 | BI28: -10.16533 | BM28: Error [%] | BN28: -0.22808452 | BO28: -0.28887819 | BP28: -2.8499581 | BQ28: 3.7480034 | BR28: 2.2805613 | BS28: -0.87675006 | BT28: 0.25039414 | BU28: -7.5302986 | BV28: -0.12062726 | BW28: -0.31672691 | BX28: -2.8561537 | BY28: 3.5956888 | BZ28: 2.6460134 | CA28: -0.93503937 | CB28: 0.059740401 | CC28: -7.1007062 | CG28: Error [%] | CH28: 27.245093 | CI28: 259.92553 | CJ28: 106.61686 | CK28: 72.32167 | CL28: 199.13924 | CM28: 227.71601 | CN28: 32.293987 | CO28: -18.140427 | CP28: 26.737035 | CQ28: 257.26496 | CR28: 106.49549 | CS28: 70.735944 | CT28: 199.29078 | CU28: 200.29108 | CV28: 33.02392 | CW28: -17.248062 | DA28: Error [%] | DB28: 413.19118 | DC28: 29.622487 | DD28: 1451.9412 | DE28: 284.16555 | DF28: 128.15585 | DG28: 98.389169 | DH28: 330.02309 | DI28: 159.70295 | DJ28: 411.05398 | DK28: 28.539483 | DL28: 1458.952 | DM28: 284.34014 | DN28: 125.51301 | DO28: 98.026088 | DP28: 331.16407 | DQ28: 160.45428 | DU28: Error [%] | DV28: -71.285335 | DW28: 212.25173 | DX28: 143.83092 | DY28: 24.769398 | DZ28: 101.69492 | EA28: 29.888512 | EB28: 661.25 | EC28: 379.20398 | ED28: -68.581237 | EE28: 212.75026 | EF28: 154.78028 | EG28: 24.797794 | EH28: 102.8128 | EI28: 31.185744 | EJ28: 658.25688 | EK28: 387.56219 | EO28: Error [%] | EP28: 387.05882 | EQ28: 970.84149 | ER28: 2358.209 | ES28: 237.40521 | ET28: 169.33656 | EU28: 164.12371 | EV28: 1147.3934 | EW28: 29.792463 | EX28: 387.05882 | EY28: 1000.362 | EZ28: 2357.8755 | FA28: 242.29339 | FB28: 167.47568 | FC28: 161.08949 | FD28: 1147.3934 | FE28: 30.676396
D29: 3D Model | E29: Ground Truth | F29: 2.99 | G29: 4.19 | H29: 5.3 | I29: 5.73 | J29: 4.24 | K29: 4.45 | L29: 1.61 | M29: 2.42 | N29: 2.99 | O29: 4.19 | P29: 5.3 | Q29: 5.73 | R29: 4.24 | S29: 4.45 | T29: 1.61 | U29: 2.42 | X29: 3D Model | Y29: Ground Truth | Z29: 2.88 | AA29: 5.38 | AB29: 5.1 | AC29: 6.21 | AD29: 5.33 | AE29: 3.71 | AF29: 2.87 | AG29: 3.05 | AH29: 2.88 | AI29: 5.38 | AJ29: 5.1 | AK29: 6.21 | AL29: 5.33 | AM29: 3.71 | AN29: 2.87 | AO29: 3.05 | AR29: 3D Model | AS29: Ground Truth | AT29: 3.83 | AU29: 4.29 | AV29: 3.95 | AW29: 4.43 | AX29: 3.64 | AY29: 3.23 | AZ29: 1.7 | BA29: 1.13 | BB29: 3.83 | BC29: 4.29 | BD29: 3.95 | BE29: 4.43 | BF29: 3.64 | BG29: 3.23 | BH29: 1.7 | BI29: 1.13 | BL29: 3D Model | BM29: Ground Truth | BN29: 4.19 | BO29: 6.13 | BP29: 3.69 | BQ29: 5.35 | BR29: 5.49 | BS29: 1.85 | BT29: 3.72 | BU29: 2.9 | BV29: 4.19 | BW29: 6.13 | BX29: 3.69 | BY29: 5.35 | BZ29: 5.49 | CA29: 1.85 | CB29: 3.72 | CC29: 2.9 | CF29: 3D Model | CG29: Ground Truth | CH29: 2.99 | CI29: 4.19 | CJ29: 5.3 | CK29: 5.73 | CL29: 4.24 | CM29: 4.45 | CN29: 1.61 | CO29: 2.42 | CP29: 2.99 | CQ29: 4.19 | CR29: 5.3 | CS29: 5.73 | CT29: 4.24 | CU29: 4.45 | CV29: 1.61 | CW29: 2.42 | CZ29: 3D Model | DA29: Ground Truth | DB29: 2.88 | DC29: 5.38 | DD29: 5.1 | DE29: 6.21 | DF29: 5.33 | DG29: 3.71 | DH29: 2.87 | DI29: 3.05 | DJ29: 2.88 | DK29: 5.38 | DL29: 5.1 | DM29: 6.21 | DN29: 5.33 | DO29: 3.71 | DP29: 2.87 | DQ29: 3.05 | DT29: 3D Model | DU29: Ground Truth | DV29: 3.83 | DW29: 4.29 | DX29: 3.95 | DY29: 4.43 | DZ29: 3.64 | EA29: 3.23 | EB29: 1.7 | EC29: 1.13 | ED29: 3.83 | EE29: 4.29 | EF29: 3.95 | EG29: 4.43 | EH29: 3.64 | EI29: 3.23 | EJ29: 1.7 | EK29: 1.13 | EN29: 3D Model | EO29: Ground Truth | EP29: 4.19 | EQ29: 6.13 | ER29: 3.69 | ES29: 5.35 | ET29: 5.49 | EU29: 1.85 | EV29: 3.72 | EW29: 2.9 | EX29: 4.19 | EY29: 6.13 | EZ29: 3.69 | FA29: 5.35 | FB29: 5.49 | FC29: 1.85 | FD29: 3.72 | FE29: 2.9
E30: Error [m] | F30: -0.01 | G30: -0.2 | H30: 0.02 | I30: 0.27 | J30: -0.08 | K30: -0.33 | L30: -0.14 | M30: 0.14 | N30: -0.0054761905 | O30: -0.198 | P30: 0.043170732 | Q30: 0.3185 | R30: -0.069512195 | S30: -0.2074359 | T30: -0.14153846 | U30: 0.12648649 | Y30: Error [m] | Z30: 0.036818182 | AA30: -0.071323529 | AB30: -0.079508197 | AC30: 0.38311475 | AD30: 0.16083333 | AE30: -0.0089230769 | AF30: -0.18030769 | AG30: -0.34933333 | AH30: 0.036829268 | AI30: -0.071818182 | AJ30: -0.076578947 | AK30: 0.45948718 | AL30: 0.175 | AM30: 0.0016666667 | AN30: -0.18538462 | AO30: -0.36351351 | AS30: Error [m] | AT30: -0.085201613 | AU30: 0.03835443 | AV30: -0.20336066 | AW30: 0.13092369 | AX30: 0.053659574 | AY30: 0.1046 | AZ30: 0.0714 | BA30: -0.1196063 | BB30: -0.089787234 | BC30: 0.022380952 | BD30: -0.20913043 | BE30: 0.12782609 | BF30: 0.038809524 | BG30: 0.10795918 | BH30: 0.07212766 | BI30: -0.11673469 | BM30: Error [m] | BN30: 0.040535714 | BO30: 0.032385321 | BP30: -0.077368421 | BQ30: 0.22219048 | BR30: 0.1712963 | BS30: 0.0038135593 | BT30: -0.030608696 | BU30: -0.24697674 | BV30: 0.045 | BW30: 0.030681818 | BX30: -0.077608696 | BY30: 0.21465116 | BZ30: 0.19023256 | CA30: 0.0027272727 | CB30: -0.037755102 | CC30: -0.23242424 | CG30: Error [m] | CH30: 0.64020408 | CI30: 3.0286486 | CJ30: 2.7445455 | CK30: 2.4280357 | CL30: 2.8292857 | CM30: 3.1104255 | CN30: 0.38545455 | CO30: -0.56071429 | CP30: 0.63078431 | CQ30: 3.02 | CR30: 2.7430435 | CS30: 2.3973684 | CT30: 2.83 | CU30: 2.9880851 | CV30: 0.39217391 | CW30: -0.52857143 | DA30: Error [m] | DB30: 2.3266 | DC30: 1.2063415 | DD30: 4.7713793 | DE30: 4.6039216 | DF30: 2.9938776 | DG30: 1.8701818 | DH30: 2.1863158 | DI30: 1.8486275 | DJ30: 2.3242857 | DK30: 1.1711765 | DL30: 4.7728571 | DM30: 4.6046512 | DN30: 2.9665 | DO30: 1.8668085 | DP30: 2.188125 | DQ30: 1.852093 | DU30: Error [m] | DV30: -9.6126087 | DW30: 2.9321212 | DX30: 2.5678947 | DY30: 0.91952381 | DZ30: 1.87 | EA30: 0.77404762 | EB30: 1.4714286 | EC30: 0.89627907 | ED30: -8.4556522 | EE30: 2.9342857 | EF30: 2.6272917 | EG30: 0.92032258 | EH30: 1.8797561 | EI30: 0.79833333 | EJ30: 1.4705263 | EK30: 0.90028571 | EO30: Error [m] | EP30: 3.34 | EQ30: 5.5622222 | ER30: 3.5411111 | ES30: 3.7732609 | ET30: 3.4702222 | EU30: 1.1571429 | EV30: 3.4185714 | EW30: 0.65795918 | EX30: 3.34 | EY30: 5.5774545 | EZ30: 3.5410909 | FA30: 3.7957778 | FB30: 3.4561702 | FC30: 1.1490909 | FD30: 3.4185714 | FE30: 0.673125
E31: Error [%] | F31: -0.34 | G31: -4.45 | H31: 0.44 | I31: 4.99 | J31: -1.92 | K31: -6.97 | L31: -7.96 | M31: 6.37 | N31: -0.18281536 | O31: -4.5123063 | P31: 0.82123138 | Q31: 5.885614 | R31: -1.6129945 | S31: -4.4538648 | T31: -8.0808081 | U31: 5.5149658 | Y31: Error [%] | Z31: 1.294964 | AA31: -1.3083709 | AB31: -1.535053 | AC31: 6.5749494 | AD31: 3.1113977 | AE31: -0.23993712 | AF31: -5.9111313 | AG31: -10.276525 | AH31: 1.295359 | AI31: -1.3173253 | AJ31: -1.4793351 | AK31: 7.9903688 | AL31: 3.3947624 | AM31: 0.04494382 | AN31: -6.0674723 | AO31: -10.649248 | AS31: Error [%] | AT31: -2.1761743 | AU31: 0.9021079 | AV31: -4.8962918 | AW31: 3.0453913 | AX31: 1.4962209 | AY31: 3.3467716 | AZ31: 4.3841336 | BA31: -9.5715186 | BB31: -2.290615 | BC31: 0.52443651 | BD31: -5.028225 | BE31: 2.9711976 | BF31: 1.077686 | BG31: 3.4579684 | BH31: 4.4307934 | BI31: -9.3632346 | BM31: Error [%] | BN31: 0.9768903 | BO31: 0.53111459 | BP31: -2.0536463 | BQ31: 4.3330485 | BR31: 3.2206399 | BS31: 0.20656415 | BT31: -0.81609942 | BU31: -7.8480638 | BV31: 1.0856454 | BW31: 0.50303685 | BX31: -2.0598927 | BY31: 4.179875 | BZ31: 3.5894511 | CA31: 0.1476378 | CB31: -1.0047249 | CC31: -7.4199478 | CG31: Error [%] | CH31: 27.245093 | CI31: 260.7866 | CJ31: 107.3995 | CK31: 73.53307 | CL31: 200.55696 | CM31: 232.19504 | CN31: 31.477357 | CO31: -18.811407 | CP31: 26.737035 | CQ31: 258.11966 | CR31: 107.27767 | CS31: 71.936197 | CT31: 200.70922 | CU31: 204.39528 | CV31: 32.202785 | CW31: -17.926357 | DA31: Error [%] | DB31: 420.41923 | DC31: 28.903693 | DD31: 1451.9412 | DE31: 286.65609 | DF31: 128.15585 | DG31: 101.65036 | DH31: 319.78445 | DI31: 153.87629 | DJ31: 418.25193 | DK31: 27.826695 | DL31: 1458.952 | DM31: 286.83181 | DN31: 125.51301 | DO31: 101.28131 | DP31: 320.89826 | DQ31: 154.61076 | DU31: Error [%] | DV31: -71.508506 | DW31: 215.93394 | DX31: 185.79589 | DY31: 26.193706 | DZ31: 105.64972 | EA31: 31.517208 | EB31: 643.75 | EC31: 383.48259 | ED31: -68.825424 | EE31: 216.43836 | EF31: 198.62971 | EG31: 26.222426 | EH31: 106.78952 | EI31: 32.830706 | EJ31: 640.82569 | EK31: 391.91542 | EO31: Error [%] | EP31: 392.94118 | EQ31: 979.64775 | ER31: 2378.3582 | ES31: 239.30787 | ET31: 171.81208 | EU31: 167.01031 | EV31: 1134.1232 | EW31: 29.346441 | EX31: 392.94118 | EY31: 1009.411 | EZ31: 2378.022 | FA31: 244.22362 | FB31: 169.93409 | FC31: 163.94293 | FD31: 1134.1232 | FE31: 30.227337
C32: 3 | D32: Mean unfiltered value | F32: 2.9465294 | G32: 4.2850318 | H32: 5.1081765 | I32: 5.1088235 | J32: 4.1863905 | K32: 4.5047647 | L32: 1.7452976 | M32: 2.2166272 | N32: 2.91075 | O32: 4.3447059 | P32: 5.30025 | Q32: 5.096 | R32: 4.2545 | S32: 4.5 | T32: 1.7476923 | U32: 2.257 | W32: 3 | X32: Mean unfiltered value | Z32: 2.7888732 | AA32: 5.0550704 | AB32: 5.0347761 | AC32: 5.0567143 | AD32: 5.195 | AE32: 3.433662 | AF32: 2.8695714 | AG32: 3.3443284 | AH32: 2.8245455 | AI32: 4.9396364 | AJ32: 4.9624074 | AK32: 5.1333333 | AL32: 5.1975 | AM32: 3.5218182 | AN32: 2.8787037 | AO32: 3.3957407 | AQ32: 3 | AR32: Mean unfiltered value | AT32: 3.7522008 | AU32: 4.1292664 | AV32: 3.9294595 | AW32: 4.1550973 | AX32: 3.4329457 | AY32: 3.0722008 | AZ32: 1.612973 | BA32: 1.2348249 | BB32: 3.7908889 | BC32: 4.1906667 | BD32: 3.8635556 | BE32: 4.0752273 | BF32: 3.5629545 | BG32: 3.0693333 | BH32: 1.5962222 | BI32: 1.2393333 | BK32: 3 | BL32: Mean unfiltered value | BN32: 3.9943636 | BO32: 5.6325714 | BP32: 3.7147273 | BQ32: 4.7845455 | BR32: 5.1445455 | BS32: 1.8173636 | BT32: 3.5009091 | BU32: 3.1810256 | BV32: 3.9608 | BW32: 5.605 | BX32: 3.4922 | BY32: 4.822 | BZ32: 5.0456 | CA32: 1.8188 | CB32: 3.4992 | CC32: 3.19 | CE32: 3 | CF32: Mean unfiltered value | CH32: 2.52 | CI32: 1.2765 | CJ32: 3.0252941 | CK32: 4.6628814 | CL32: 1.5981356 | CM32: 7.8286275 | CN32: 1.0691525 | CO32: 2.8926316 | CP32: 2.5569388 | CQ32: 1.32325 | CR32: 3.1364706 | CS32: 4.792 | CT32: 1.4898333 | CU32: 9.5643137 | CV32: 1.0623729 | CW32: 3.1775 | CY32: 3 | CZ32: Mean unfiltered value | DB32: 0.60559322 | DC32: 3.0669492 | DD32: 0.51305085 | DE32: 1.7684746 | DF32: 4.3098305 | DG32: 2.5411864 | DH32: 0.67271186 | DI32: 1.3669091 | DJ32: 0.60716667 | DK32: 2.954 | DL32: 0.51566667 | DM32: 1.7936667 | DN32: 4.3856667 | DO32: 2.6581667 | DP32: 0.67183333 | DQ32: 1.3705357 | DS32: 3 | DT32: Mean unfiltered value | DV32: 12.457627 | DW32: 1.3692453 | DX32: 1.979661 | DY32: 2.9963462 | DZ32: 1.6859322 | EA32: 2.6350847 | EB32: 0.22561404 | EC32: 0.29677966 | ED32: 12.373 | EE32: 1.3788889 | EF32: 1.8291667 | EG32: 2.9844231 | EH32: 1.6853333 | EI32: 2.5891667 | EJ32: 0.22566667 | EK32: 0.30883333 | EM32: 3 | EN32: Mean unfiltered value | EP32: 0.81081633 | EQ32: 0.93559322 | ER32: 0.14677966 | ES32: 2.0262222 | ET32: 1.9522222 | EU32: 0.61084746 | EV32: 0.32932203 | EW32: 2.4113559 | EX32: 0.81571429 | EY32: 0.93854545 | EZ32: 0.14872727 | FA32: 2.0271429 | FB32: 1.9284314 | FC32: 0.62654545 | FD32: 0.32581818 | FE32: 2.4072727
